Traceback (most recent call last):
  File "./frankenstein.py", line 433, in <module>
    frank.runlive()
  File "./frankenstein.py", line 393, in runlive
    self.check()
  File "./frankenstein.py", line 268, in check
    print 'start_vwap', data.iloc[0].name,
  File "d:\anaconda2\lib\site-packages\pandas\core\indexing.py", line 1312, in __getitem__
    return self._getitem_axis(key, axis=0)
  File "d:\anaconda2\lib\site-packages\pandas\core\indexing.py", line 1628, in _getitem_axis
    self._is_valid_integer(key, axis)
  File "d:\anaconda2\lib\site-packages\pandas\core\indexing.py", line 1542, in _is_valid_integer
    raise IndexError("single positional indexer is out-of-bounds")
IndexError: single positional indexer is out-of-bounds
